Workbook

Sheet Dane do korelacji
A1: rok | B1: 8 - Track | C1: Cassette | D1: Cassette Single | E1: LP/EP | F1: Other Tapes | G1: Vinyl Single | H1: CD | I1: SACD | J1: CD Single | K1: DVD Audio | L1: Music Video (Physical) | M1: Download Album | N1: Download Music Video | O1: Download Single | P1: Ringtones & Ringbacks | Q1: SoundExchange Distributions | R1: Paid Subscription | S1: Synchronization | T1: Other Digital | U1: Other Ad-Supported Streaming | V1: On-Demand Streaming (Ad-Supported) | W1: Limited Tier Paid Subscription | X1: Kiosk
A2: 1973 | B2: 3355.8 | C2: 521.6 | E2: 8550.9 | F2: 107.1 | G2: 1303.9
A3: 1974 | B3: 3394.4 | C3: 538.9 | E3: 8380.9 | F3: 82.2 | G3: 1199
A4: 1975 | B4: 3301.9 | C4: 559.6 | E4: 8410.5 | F4: 57.8 | G4: 1197.9
A5: 1976 | B5: 3631.8 | C5: 780.2 | E5: 8905.4 | F5: 27.3 | G5: 1312.5
A6: 1977 | B6: 4077.8 | C6: 1255 | E6: 11037.2 | G6: 1232.4
A7: 1978 | B7: 4430.3 | C7: 2102.1 | E7: 11558.6 | G7: 1216.5
A8: 1979 | B8: 2872 | C8: 2436.8 | E8: 8633.2 | G8: 1484.1
A9: 1980 | B9: 1948.8 | C9: 2607 | E9: 8135.2 | G9: 924.5
A10: 1981 | B10: 1049.2 | C10: 3562.6 | E10: 7849.5 | G10: 859.5
A11: 1982 | B11: 113.7 | C11: 4371.6 | E11: 6078.6 | G11: 893.6
A12: 1983 | C12: 5540 | E12: 5167.1 | G12: 823.9 | H12: 52.6
A13: 1984 | C13: 6991.1 | E13: 4542.1 | G13: 876 | H13: 302.9
A14: 1985 | C14: 6828.9 | E14: 3626.1 | G14: 795.7 | H14: 1103
A15: 1986 | C15: 6948.9 | E15: 2732.9 | G15: 634.1 | H15: 2585.8
A16: 1987 | C16: 7938.6 | D16: 38.4 | E16: 2127.3 | G16: 545.3 | H16: 4274.4
A17: 1988 | C17: 8718.9 | D17: 147.6 | E17: 1370.8 | G17: 464.7 | H17: 5382.9 | J17: 25.2
A18: 1989 | C18: 8221.5 | D18: 478.2 | E18: 541.3 | G18: 286 | H18: 6358.7 | L18: 283.6
A19: 1990 | C19: 8095.2 | D19: 601.2 | E19: 201.7 | G19: 220.1 | H19: 8046.7 | J19: 14 | L19: 401.7
A20: 1991 | C20: 6755.3 | D20: 515.4 | E20: 65.8 | G20: 143 | H20: 9704.2 | J20: 78.5 | L20: 264.2
A21: 1992 | C21: 6767.9 | D21: 648.9 | E21: 29.3 | G21: 144.2 | H21: 11568 | J21: 97.9 | L21: 341.8
A22: 1993 | C22: 6148.4 | D22: 629.4 | E22: 22.4 | G22: 108 | H22: 13730.4 | J22: 96.6 | L22: 449.8
A23: 1994 | C23: 6119.5 | D23: 565.2 | E23: 36.6 | G23: 97 | H23: 17403.2 | J23: 115.3 | L23: 475.1
A24: 1995 | C24: 4605.7 | D24: 472.4 | E24: 50.2 | G24: 93.4 | H24: 18748.8 | J24: 221.7 | L24: 440.5
A25: 1996 | C25: 3700.1 | D25: 367.6 | E25: 71.5 | G25: 92.2 | H25: 19293.3 | J25: 357.5 | L25: 458.5
A26: 1997 | C26: 2890.8 | D26: 253.4 | E26: 63.2 | G26: 67.6 | H26: 18823.4 | J26: 517.7 | L26: 614.9
A27: 1998 | C27: 2654.3 | D27: 176.5 | E27: 63.6 | G27: 48 | H27: 21340.4 | J27: 398.5 | L27: 949.6
A28: 1999 | C28: 1941.6 | D28: 87.8 | E28: 58.2 | G28: 51 | H28: 23440.3 | J28: 406.8 | L28: 689
A29: 2000 | C29: 1107.7 | D29: 8.1 | E29: 49 | G29: 46.5 | H29: 23382.6 | J29: 252.5 | L29: 498.8
A30: 2001 | C30: 625.2 | E30: 47.1 | G30: 54 | H30: 22210.7 | J30: 136.6 | K30: 10.3 | L30: 566.4
A31: 2002 | C31: 355.3 | E31: 34.7 | G31: 42.2 | H31: 20399.5 | J31: 33.2 | K31: 14.4 | L31: 488.5
A32: 2003 | C32: 179 | E32: 35.9 | G32: 35.6 | H32: 18601.6 | I32: 43.6 | J32: 59.6 | K32: 13.2 | L32: 662.2
A33: 2004 | C33: 38.2 | E33: 31.1 | G33: 32.1 | H33: 18463.6 | I33: 26.8 | J33: 24.2 | K33: 10.5 | L33: 979.4 | M33: 73.4 | O33: 222.6 | Q33: 11.1
A34: 2005 | C34: 20.4 | E34: 22.2 | G34: 20.6 | H34: 16413.3 | I34: 15.6 | J34: 17 | K34: 17.5 | L34: 939.5 | M34: 211.7 | N34: 5.8 | O34: 566.8 | P34: 657.8 | Q34: 31.8 | R34: 232.8 | X34: 1.6
A35: 2006 | C35: 5.6 | E35: 23.7 | G35: 15 | H35: 14165.9 | I35: 8.3 | J35: 11.6 | K35: 3.6 | L35: 681.8 | M35: 417 | N35: 29.8 | O35: 877.5 | P35: 1169.5 | Q35: 49.6 | R35: 311.7 | X35: 2.9
A36: 2007 | C36: 4.4 | E36: 33.7 | G36: 5.9 | H36: 10951.6 | I36: 5.3 | J36: 17.9 | K36: 4.1 | L36: 712.6 | M36: 731 | N36: 41.4 | O36: 1191.8 | P36: 1551.6 | Q36: 53.2 | R36: 343.9 | X36: 3.8
A37: 2008 | C37: 1.3 | E37: 80.2 | G37: 4.1 | H37: 7743.1 | I37: 4.4 | J37: 5 | K37: 1.7 | L37: 321.7 | M37: 899.1 | N37: 58.4 | O37: 1460.8 | P37: 1382.8 | Q37: 141.5 | R37: 313.3 | X37: 3.7
A38: 2009 | E38: 90.6 | G38: 3.6 | H38: 6133.9 | I38: 3.4 | J38: 4.4 | K38: 2.3 | L38: 297.7 | M38: 1057.1 | N38: 58.1 | O38: 1664.6 | P38: 998.2 | Q38: 220.9 | R38: 292.9 | S38: 285.8 | X38: 8.9
A39: 2010 | E39: 124.2 | G39: 3.2 | H39: 4736.2 | I39: 2.4 | J39: 4.1 | K39: 1.3 | L39: 248.2 | M39: 1219.1 | N39: 51.1 | O39: 1867.4 | P39: 626 | Q39: 348.2 | R39: 296.8 | S39: 263.7 | X39: 8.9
A40: 2011 | E40: 161.7 | G40: 6.2 | H40: 4200.2 | I40: 2 | J40: 4.7 | K40: 0.4 | L40: 204.5 | M40: 1450.5 | N40: 43.9 | O40: 2062.2 | P40: 374.1 | Q40: 395.5 | R40: 335.7 | S40: 266.2 | V40: 154.2 | X40: 3.7
...

Sheet Obliczenia
A1: ='Długość albumów'!B23 -> Długość w minutach | B1: ='Długość albumów'!C23 -> Ilość | C1: środek i-tej klasy | D1: ni*xi | E1: xi-średnia | F1: do kwadratu | G1: razy ni | H1: do sześcianu | I1: razy ni | J1: do 4 | K1: razy ni | N1: Analogowe | O1: Kompaktowe | P1: xi-średnia | Q1: yi-średnia | R1: Pi*Qi | S1: Pi^2
A2: ='Długość albumów'!B24 -> [11-22] | B2: ='Długość albumów'!C24 -> 10 | C2: 16.5 | D2: =C2*B2 -> 165 | E2: =C2-D$13 -> -29.465 | F2: =E2^2 -> 868.18623 | G2: =F2*B2 -> 8681.8623 | H2: =E2*E2*E2 -> -25581.107 | I2: =H2*B2 -> -255811.07 | J2: =F2^2 -> 753747.32 | K2: =J2*B2 -> 7537473.2 | M2: ='Dane do korelacji'!A12 -> 1983 | N2: =SUM('Dane do korelacji'!B12:G12) -> 11531 | O2: =SUM('Dane do korelacji'!H12:L12) -> 52.6 | P2: =N2-N$20 -> 3759.8824 | Q2: =O2-O$20 -> -11115.482 | R2: =P2*Q2 -> -41792906 | S2: =P2^2 -> 14136715
A3: ='Długość albumów'!B25 -> (22-34] | B3: ='Długość albumów'!C25 -> 21 | C3: 28 | D3: =C3*B3 -> 588 | E3: =C3-D$13 -> -17.965 | F3: =E3^2 -> 322.74123 | G3: =F3*B3 -> 6777.5657 | H3: =E3*E3*E3 -> -5798.0461 | I3: =H3*B3 -> -121758.97 | J3: =F3^2 -> 104161.9 | K3: =J3*B3 -> 2187399.9 | M3: ='Dane do korelacji'!A13 -> 1984 | N3: =SUM('Dane do korelacji'!B13:G13) -> 12409.2 | O3: =SUM('Dane do korelacji'!H13:L13) -> 302.9 | P3: =N3-N$20 -> 4638.0824 | Q3: =O3-O$20 -> -10865.182 | R3: =P3*Q3 -> -50393611 | S3: =P3^2 -> 21511808
A4: ='Długość albumów'!B26 -> (34-46] | B4: ='Długość albumów'!C26 -> 24 | C4: 40 | D4: =C4*B4 -> 960 | E4: =C4-D$13 -> -5.965 | F4: =E4^2 -> 35.581225 | G4: =F4*B4 -> 853.9494 | H4: =E4*E4*E4 -> -212.24201 | I4: =H4*B4 -> -5093.8082 | J4: =F4^2 -> 1266.0236 | K4: =J4*B4 -> 30384.566 | M4: ='Dane do korelacji'!A14 -> 1985 | N4: =SUM('Dane do korelacji'!B14:G14) -> 11250.7 | O4: =SUM('Dane do korelacji'!H14:L14) -> 1103 | P4: =N4-N$20 -> 3479.5824 | Q4: =O4-O$20 -> -10065.082 | R4: =P4*Q4 -> -35022283 | S4: =P4^2 -> 12107493
A5: ='Długość albumów'!B27 -> (46-58] | B5: ='Długość albumów'!C27 -> 25 | C5: 52 | D5: =C5*B5 -> 1300 | E5: =C5-D$13 -> 6.035 | F5: =E5^2 -> 36.421225 | G5: =F5*B5 -> 910.53062 | H5: =E5*E5*E5 -> 219.80209 | I5: =H5*B5 -> 5495.0523 | J5: =F5^2 -> 1326.5056 | K5: =J5*B5 -> 33162.641 | M5: ='Dane do korelacji'!A15 -> 1986 | N5: =SUM('Dane do korelacji'!B15:G15) -> 10315.9 | O5: =SUM('Dane do korelacji'!H15:L15) -> 2585.8 | P5: =N5-N$20 -> 2544.7824 | Q5: =O5-O$20 -> -8582.2824 | R5: =P5*Q5 -> -21840041 | S5: =P5^2 -> 6475917.2
A6: ='Długość albumów'!B28 -> (58-70] | B6: ='Długość albumów'!C28 -> 7 | C6: 64 | D6: =C6*B6 -> 448 | E6: =C6-D$13 -> 18.035 | F6: =E6^2 -> 325.26122 | G6: =F6*B6 -> 2276.8286 | H6: =E6*E6*E6 -> 5866.0862 | I6: =H6*B6 -> 41062.603 | J6: =F6^2 -> 105794.86 | K6: =J6*B6 -> 740564.05 | M6: ='Dane do korelacji'!A16 -> 1987 | N6: =SUM('Dane do korelacji'!B16:G16) -> 10649.6 | O6: =SUM('Dane do korelacji'!H16:L16) -> 4274.4 | P6: =N6-N$20 -> 2878.4824 | Q6: =O6-O$20 -> -6893.6824 | R6: =P6*Q6 -> -19843343 | S6: =P6^2 -> 8285660.7
A7: ='Długość albumów'!B29 -> (70-82] | B7: ='Długość albumów'!C29 -> 8 | C7: 76 | D7: =C7*B7 -> 608 | E7: =C7-D$13 -> 30.035 | F7: =E7^2 -> 902.10122 | G7: =F7*B7 -> 7216.8098 | H7: =E7*E7*E7 -> 27094.61 | I7: =H7*B7 -> 216756.88 | J7: =F7^2 -> 813786.62 | K7: =J7*B7 -> 6510293 | M7: ='Dane do korelacji'!A17 -> 1988 | N7: =SUM('Dane do korelacji'!B17:G17) -> 10702 | O7: =SUM('Dane do korelacji'!H17:L17) -> 5408.1 | P7: =N7-N$20 -> 2930.8824 | Q7: =O7-O$20 -> -5759.9824 | R7: =P7*Q7 -> -16881831 | S7: =P7^2 -> 8590071.4
A8: ='Długość albumów'!B30 -> (82-129] | B8: ='Długość albumów'!C30 -> 5 | C8: 105.5 | D8: =C8*B8 -> 527.5 | E8: =C8-D$13 -> 59.535 | F8: =E8^2 -> 3544.4162 | G8: =F8*B8 -> 17722.081 | H8: =E8*E8*E8 -> 211016.82 | I8: =H8*B8 -> 1055084.1 | J8: =F8^2 -> 12562886 | K8: =J8*B8 -> 62814432 | M8: ='Dane do korelacji'!A18 -> 1989 | N8: =SUM('Dane do korelacji'!B18:G18) -> 9527 | O8: =SUM('Dane do korelacji'!H18:L18) -> 6642.3 | P8: =N8-N$20 -> 1755.8824 | Q8: =O8-O$20 -> -4525.7824 | R8: =P8*Q8 -> -7946741.4 | S8: =P8^2 -> 3083122.8
D9: =SUM(D2:D8) -> 4596.5 | F9: =SUM(F2:F8) -> 6034.7086 | G9: =SUM(G2:G8) -> 44439.628 | I9: =SUM(I2:I8) -> 935734.79 | K9: =SUM(K2:K8) -> 79853709 | M9: ='Dane do korelacji'!A19 -> 1990 | N9: =SUM('Dane do korelacji'!B19:G19) -> 9118.2 | O9: =SUM('Dane do korelacji'!H19:L19) -> 8462.4 | P9: =N9-N$20 -> 1347.0824 | Q9: =O9-O$20 -> -2705.6824 | R9: =P9*Q9 -> -3644777 | S9: =P9^2 -> 1814630.9
F10: =F9/100 -> 60.347086 | G10: =G9/100 -> 444.39628 | I10: =I9/100 -> 9357.3479 | K10: =K9/100 -> 798537.09 | M10: ='Dane do korelacji'!A20 -> 1991 | N10: =SUM('Dane do korelacji'!B20:G20) -> 7479.5 | O10: =SUM('Dane do korelacji'!H20:L20) -> 10046.9 | P10: =N10-N$20 -> -291.61765 | Q10: =O10-O$20 -> -1121.1824 | R10: =P10*Q10 -> 326956.56 | S10: =P10^2 -> 85040.852
D11: =AVERAGE(D2:D8) -> 656.64286 | F11: =SQRT(F10) -> 7.7683387 | M11: ='Dane do korelacji'!A21 -> 1992 | N11: =SUM('Dane do korelacji'!B21:G21) -> 7590.3 | O11: =SUM('Dane do korelacji'!H21:L21) -> 12007.7 | P11: =N11-N$20 -> -180.81765 | Q11: =O11-O$20 -> 839.61765 | R11: =P11*Q11 -> -151817.69 | S11: =P11^2 -> 32695.021
M12: ='Dane do korelacji'!A22 -> 1993 | N12: =SUM('Dane do korelacji'!B22:G22) -> 6908.2 | O12: =SUM('Dane do korelacji'!H22:L22) -> 14276.8 | P12: =N12-N$20 -> -862.91765 | Q12: =O12-O$20 -> 3108.7176 | R12: =P12*Q12 -> -2682567.3 | S12: =P12^2 -> 744626.87
D13: ='Długość albumów'!Q22 -> 45.965 | M13: ='Dane do korelacji'!A23 -> 1994 | N13: =SUM('Dane do korelacji'!B23:G23) -> 6818.3 | O13: =SUM('Dane do korelacji'!H23:L23) -> 17993.6 | P13: =N13-N$20 -> -952.81765 | Q13: =O13-O$20 -> 6825.5176 | R13: =P13*Q13 -> -6503473.7 | S13: =P13^2 -> 907861.47
M14: ='Dane do korelacji'!A24 -> 1995 | N14: =SUM('Dane do korelacji'!B24:G24) -> 5221.7 | O14: =SUM('Dane do korelacji'!H24:L24) -> 19411 | P14: =N14-N$20 -> -2549.4176 | Q14: =O14-O$20 -> 8242.9176 | R14: =P14*Q14 -> -21014640 | S14: =P14^2 -> 6499530.3
E15: =(E2^3)*B2 -> -255811.07 | M15: ='Dane do korelacji'!A25 -> 1996 | N15: =SUM('Dane do korelacji'!B25:G25) -> 4231.4 | O15: =SUM('Dane do korelacji'!H25:L25) -> 20109.3 | P15: =N15-N$20 -> -3539.7176 | Q15: =O15-O$20 -> 8941.2176 | R15: =P15*Q15 -> -31649386 | S15: =P15^2 -> 12529601
M16: ='Dane do korelacji'!A26 -> 1997 | N16: =SUM('Dane do korelacji'!B26:G26) -> 3275 | O16: =SUM('Dane do korelacji'!H26:L26) -> 19956 | P16: =N16-N$20 -> -4496.1176 | Q16: =O16-O$20 -> 8787.9176 | R16: =P16*Q16 -> -39511512 | S16: =P16^2 -> 20215074
M17: ='Dane do korelacji'!A27 -> 1998 | N17: =SUM('Dane do korelacji'!B27:G27) -> 2942.4 | O17: =SUM('Dane do korelacji'!H27:L27) -> 22688.5 | P17: =N17-N$20 -> -4828.7176 | Q17: =O17-O$20 -> 11520.418 | R17: =P17*Q17 -> -55628844 | S17: =P17^2 -> 23316514
M18: ='Dane do korelacji'!A28 -> 1999 | N18: =SUM('Dane do korelacji'!B28:G28) -> 2138.6 | O18: =SUM('Dane do korelacji'!H28:L28) -> 24536.1 | P18: =N18-N$20 -> -5632.5176 | Q18: =O18-O$20 -> 13368.018 | R18: =P18*Q18 -> -75295595 | S18: =P18^2 -> 31725255
M19: suma | N19: =SUM(N2:N18) -> 132109 | O19: =SUM(O2:O18) -> 189857.4 | R19: =SUM(R2:R18) -> -4.2947641e+08
M20: średnia | N20: =AVERAGE('Analogi vs kompakty'!B2:B18) -> 7771.1176 | O20: =AVERAGE('Analogi vs kompakty'!C2:C18) -> 11168.082 | R20: =R19/N22 -> -25263318 | S20: =AVERAGE(S2:S18) -> 10121272
S21: =SQRT(S20) -> 3181.3946
M22: N= | N22: 17
M23: odchylenie stand | N23: =_xlfn.STDEV.P(N2:N18) -> 3181.3946 | O23: =_xlfn.STDEV.P(O2:O18) -> 8116.1697

Sheet Surowe dane
A1: # | B1: g# | C1: Cover | D1: Album | E1: Streams | F1: Daily | G1: Długość albumu | H1: Minuty | J1: Dane potrzebne do stworzenia szeregu rozdzielczego przedziałowego
A2: 1 | B2: 78 | D2: Mañana Será Bonito Karol G | E2: 5585696428 | F2: 6423966 | G2: 0.036712963 | H2: 53
A3: 2 | B3: 105 | D3: One Thing At A Time Morgan Wallen | E3: 4909262111 | F3: 8968559 | G3: 0.077777778 | H3: =60+52 -> 112 | J3: Wartość minimalna | K3: Xmax= | L3: =MAX(H2:H101) -> 129
A4: 3 | B4: 138 | D4: Génesis Peso Pluma | E4: 4379165763 | F4: 6051553 | G4: 0.037615741 | H4: 54 | J4: Wartość maksymalna | K4: Xmin= | L4: =MIN(H2:H101) -> 11
A5: 4 | B5: 158 | D5: Drive Tiësto | E5: 4069486854 | F5: 3379795 | G5: 0.022152778 | H5: 32 | J5: Liczba danych | K5: N= | L5: 100
A6: 5 | B6: 184 | D6: Nadie Sabe Lo Que Va A Pasar Mañana Bad Bunny | E6: 3804560306 | F6: 6120418 | G6: 0.05625 | H6: 81 | J6: Liczba klas | K6: k= | L6: =SQRT(L5) -> 10
A7: 6 | B7: 185 | D7: Utopia Travis Scott | E7: 3801726457 | F7: 7829404 | G7: 0.050694444 | H7: 73 | J7: Rozstęp | K7: R= | L7: =L3-L4 -> 118
A8: 7 | B8: 191 | D8: 1989 (Taylor's Version) Taylor Swift | E8: 3710737740 | F8: 5544071 | G8: 0.053472222 | H8: 77 | J8: Rozpięość | K8: r= | L8: =L7/L6 -> 11.8
A9: 8 | B9: 216 | D9: Golden Jung Kook | E9: 3502609450 | F9: 6708825 | G9: 0.022060185 | H9: 32
A10: 9 | B10: 219 | D10: Meduza Meduza | E10: 3492209792 | F10: 1479144 | G10: 0.022592593 | H10: 33
A11: 10 | B11: 236 | D11: El Comienzo Grupo Frontera | E11: 3362224709 | F11: 4640936 | G11: 0.024143519 | H11: 35
A12: 11 | B12: 253 | D12: Guts Olivia Rodrigo | E12: 3246790110 | F12: 7851162 | G12: 0.027291667 | H12: 39
A13: 12 | B13: 268 | D13: Another Friday Night Joel Corry | E13: 3144900808 | F13: 1332376 | G13: 0.034664352 | H13: 50
A14: 13 | B14: 286 | D14: Barbie The Album Various Artists | E14: 3007613937 | F14: 3824366 | G14: 0.030729167 | H14: 44
A15: 14 | B15: 315 | D15: Endless Summer Vacation Miley Cyrus | E15: 2841969343 | F15: 2828849 | G15: 0.032314815 | H15: 47
A16: 15 | B16: 353 | D16: For All The Dogs Drake | E16: 2709667972 | F16: 4158120 | G16: 0.058333333 | H16: 84
A17: 16 | B17: 389 | D17: Donde Quiero Estar Quevedo | E17: 2585784588 | F17: 1781125 | G17: 0.033125 | H17: 48
A18: 17 | B18: 421 | D18: Petals To Thorns D4vd | E18: 2479284950 | F18: 2681430 | G18: 0.020046296 | H18: 29
A19: 18 | B19: 430 | D19: 2000 Manuel Turizo | E19: 2450779482 | F19: 2925002 | G19: 0.031608796 | H19: 46
A20: 19 | B20: 440 | D20: Speak Now (Taylor's Version) Taylor Swift | E20: 2401141030 | F20: 2771385 | G20: 0.072222222 | H20: 104
... A51: 50 | B51: 1116 | D51: Gettin' Old Luke Combs | E51: 1233795732 | F51: 2836527 | G51: 0.045833333 | H51: 66
A52: 51 | B52: 1121 | D52: Sugar Papi Marshmello | E52: 1229627313 | F52: 2117256 | H52: 30
A53: 52 | B53: 1135 | D53: Every Cloud - Silver Linings Sigala | E53: 1213711818 | F53: 504409 | H53: 34
A54: 53 | B54: 1141 | D54: Religiously. The Album. Bailey Zimmerman | E54: 1208402421 | F54: 1916153 | H54: 53
A55: 54 | B55: 1167 | D55: Fábula Mahalini | E55: 1188789608 | F55: 1532663 | H55: 40
A56: 55 | B56: 1170 | D56: Hello This Is The Setlist For My Tour Gayle | E56: 1187710529 | F56: 326978 | H56: 51
A57: 56 | B57: 1213 | D57: Red Moon In Venus Kali Uchis | E57: 1147125945 | F57: 1241668 | H57: 43
A58: 57 | B58: 1227 | D58: The Land Is Inhospitable And So Are We Mitski | E58: 1140244459 | F58: 2651626 | H58: 32
A59: 58 | B59: 1235 | D59: Unreal Unearth Hozier | E59: 1128949507 | F59: 7279588 | H59: 62
A60: 59 | B60: 1238 | D60: Phoenix Elley Duhé | E60: 1126422629 | F60: 748736 | H60: 45
A61: 60 | B61: 1240 | D61: To Be (Ao Vivo) Henrique & Juliano | E61: 1123698892 | F61: 2877885 | H61: 20
A62: 61 | B62: 1254 | D62: A Million Ways To Murder Kordhell | E62: 1115309630 | F62: 959470 | H62: 32
A63: 62 | B63: 1264 | D63: Did You Know That There's A Tunnel Under Ocean Blvd Lana Del Rey | E63: 1109060707 | F63: 1833770 | H63: 77
... A101: 100 | B101: 2117 | D101: Trustfall P!nk | E101: 715962208 | F101: 900991 | H101: 44
H102: =SUM(H2:H101) -> 4670

Sheet Długość albumów
A1: Postanowiłem zbadać gługośc 100 najwiekszych (najczęściej słuchanych na spotify) albumumów muzycznych wydanych w roku 2023. Surowe dane można znaleźć w arkuszu "Surowe dane". Na ich podstawie wyliczyłem liczbę klas potrzebnych do stworzenia szeregu rozdzielczego przedziałowy.
B4: Długość w minutach | C4: Ilość
B5: [11-22] | C5: 10 | E5: Z obliczonych wcześniej danych możemy stworzyć dany szereg, na podstawie którego można stwożyć następujący histogram | V5: ='Surowe dane'!J3 -> Wartość minimalna | W5: ='Surowe dane'!L4 -> 11
B6: (22-34] | C6: 21 | V6: =O24 -> Kwartyl 1 | W6: =Q24 -> 30.571429 | Y6: Jak widać, maksymalna długosć badanych płyt jest skrajnie większa od 3 kwartyla opisującego ich długość. Możemy wywnioskować, że 25% badanych albumów ma długość od 57 do 129 minut. To świadczy o tym, że mało mamy popularnych albumów o długości znacząco odbiegających od normy, a jeśli już są, to są to pojedyńcze przypadki.
B7: (34-46] | C7: 24 | R7: Xmax= | S7: =W9 -> 129 | V7: =O23 -> Mediana | W7: =Q23 -> 43.5
B8: (46-58] | C8: 25 | V8: =O25 -> Kwartyl 3 | W8: =Q25 -> 55.6
B9: (58-70] | C9: 7 | V9: ='Surowe dane'!J4 -> Wartość maksymalna | W9: ='Surowe dane'!L3 -> 129
B10: (70-82] | C10: 8
B11: (82-94] | C11: 2 | V11: =V5 -> Wartość minimalna | W11: =W5 -> 11
B12: (94-106] | C12: 1 | V12: =V6 -> Kwartyl 1 | W12: =W6-W5 -> 19.571429
B13: (106-118] | C13: 1 | R13: Q3= | S13: =W8 -> 55.6 | V13: =V7 -> Mediana | W13: =W7-W6 -> 12.928571
B14: (118-129] | C14: 1 | R14: Me= | S14: =W7 -> 43.5 | V14: =V8 -> Kwartyl 3 | W14: =W8-W7 -> 12.1
R15: Q1= | S15: =W6 -> 30.571429 | V15: =V9 -> Wartość maksymalna | W15: =W9-W8 -> 73.4
R17: Xmin= | S17: =W5 -> 11
O21: Miary tendencji środkowej
O22: Średnia arytmetyczna | P22: x= | Q22: =Obliczenia!D9/'Surowe dane'!L5 -> 45.965 | S22: Możemy powiedzieć, że 25% badanych albumów trwa nie dłużej niż 31 minut, a kolejne 25% twa nie krócej niż 57 minut. Ponadto połowa wszytskich albumów ma długość nie dłuższą, a druga połowa nie krótszą niż 44 minuty. Dodatkowo najwięcej badanych albumów ma około 47 minut. Średnio jednak wszytskie badane albumy trwają około 46 minut, a więc ponad połowa badanych alnumów była krótsza niż 46 min.
A23: Lp. | B23: =B4 -> Długość w minutach | C23: =C4 -> Ilość | E23: Połączę jednak ostatnie 4 klasy w jedną, ponieważ ich wartości w znaczący sposób odbiegają od reszty, dostając w ten sposób następujący szereg, dla którego którego będę analizował dane | O23: Mediana | P23: Me= | Q23: =34+(((100/2)-SUM(C24:C25))/C26)*12 -> 43.5
A24: 1 | B24: =B5 -> [11-22] | C24: =C5 -> 10 | O24: Kwartyl 1 | P24: Q1= | Q24: =22+(((100/4)-C24)/C25)*12 -> 30.571429
A25: 2 | B25: =B6 -> (22-34] | C25: =C6 -> 21 | O25: Kwartyl 3 | P25: Q3= | Q25: =46+((((3*100)/4)-SUM(C24:C26))/C27)*12 -> 55.6
A26: 3 | B26: =B7 -> (34-46] | C26: =C7 -> 24 | O26: Dominanta | P26: D= | Q26: =46+((C27-C26)/((C27-C26)+(C27-C28)))*12 -> 46.631579
A27: 4 | B27: =B8 -> (46-58] | C27: =C8 -> 25
A28: 5 | B28: =B9 -> (58-70] | C28: =C9 -> 7
A29: 6 | B29: =B10 -> (70-82] | C29: =C10 -> 8 | O29: Miary rozproszenia
A30: 7 | B30: (82-129] | C30: =SUM(C11:C14) -> 5 | O30: Wariancja | P30: s^2= | Q30: =Obliczenia!G9/100 -> 444.39628 | S30: Większość badanych albumów mieści się w przedziale typowym, czyli trwają od około 25 do około 67 minut. Natomiast różnica w długości trwania połowy badanych albumów wynosi tylko 25 minut, mimo tego że różnica między najdłuższym, a najkrótszym badanym albumem wynosi aż 118 minut. Możemy zaobserwować jednak dosyć dużą zmienność badanych albumów, czyli duże zróżnicowanie długości płyt względem ich średniej arytmetycznej
O31: Odchylenie standardowe | P31: s= | Q31: =SQRT(Q30) -> 21.080709
O32: Współczynnik zmienności | P32: v= | Q32: =Q31/Q22 -> 0.45862523
O33: Rozstęp | P33: R= | Q33: 118
O34: Rozstęp międzykwartylowy | P34: IQR= | Q34: =Q25-Q24 -> 25.028571
O37: Miary asymetrii i koncentracji
O38: 1 wsp. Pearson'a | P38: AP1= | Q38: =(Q22-Q26)/Q31 -> -0.031620329 | S38: Możemy zaobserwować bardzo dużą asymetrę danych. Najwięcej danych (albumów) jest skupionych z lewej strony wykresu, bliżej mediany, czyli mają długość zbliżoną do 44 minut. Po dominancie, czyli za albumami mającymi do 47 minut widzimy gwałtowny spadek w liczebnośc. Oznacza to, że mała liczba badanych albumów ma długość większa od dominanty. Na histogramie zaś możemy zaobserwować rozkład platokurtyczny, jednak sporo danych jest skupionych wokuł mediany, co może wzbudzić wrażenie, że jest on bardziej mezokurtyczny.
O39: 2 wsp. Pearson'a | P39: AP2= | Q39: =(3*(Q22-Q23))/Q31 -> 0.35079466
O40: Klasyczny wsp. Asymetrii | P40: A= | Q40: =Obliczenia!I10/('Długość albumów'!Q31^3) -> 0.99884284
O41: Kurtoza | P41: K= | Q41: =Obliczenia!K10/('Długość albumów'!Q31^4) -> 4.0434705
O42: Wsp. escesu | P42: K'= | Q42: =3-Q41 -> -1.0434705

Sheet Analogi vs kompakty
A1: rok | B1: Analogowe | C1: Kompaktowe | E1: Weźmy teraz dane dotyczące przyodów odpowiedznio przychodów ze sprzedaży płyt kompaktowych oraz nośników analogowych od roku do 1983 do 1999 w miliardach. Na ich podstawie będziemy badać korelacje | W1: Szeregi czasowe (dla nośników kompaktowych)
A2: ='Dane do korelacji'!A12 -> 1983 | B2: =SUM('Dane do korelacji'!B12:G12) -> 11531 | C2: =SUM('Dane do korelacji'!H12:L12) -> 52.6
A3: ='Dane do korelacji'!A13 -> 1984 | B3: =SUM('Dane do korelacji'!B13:G13) -> 12409.2 | C3: =SUM('Dane do korelacji'!H13:L13) -> 302.9 | R3: Możemy równiesz dla naszych danych obliczyć coroczne przyrosty i indeksy. Weźmy sobie na pierwszy plan wartości płyt kompaktowych między rokiem 1983 a 1999 | W3: Przyrosty | AA3: Indeksy
A4: ='Dane do korelacji'!A14 -> 1985 | B4: =SUM('Dane do korelacji'!B14:G14) -> 11250.7 | C4: =SUM('Dane do korelacji'!H14:L14) -> 1103 | W4: Absolutne | Y4: Względne | AA4: Indywidualne | AE4: Jak widać między rokiem 1983, a 1999 widzimy coroczny wzrost wartośći płyt kompaktowych nwzględem roku poprzedzającego, lub bazowego. Jedynie rok 1997 przyniósł minimalny spadek wartości względem poprzedzającego go roku, wynoszący -153,3 mld, lub -0,76%
A5: ='Dane do korelacji'!A15 -> 1986 | B5: =SUM('Dane do korelacji'!B15:G15) -> 10315.9 | C5: =SUM('Dane do korelacji'!H15:L15) -> 2585.8 | V5: rok | W5: Jedno podstawowe | X5: łańcuchowe | Y5: Jedno podstawowe | Z5: łańcuchowe | AA5: Jedno podstawowe | AB5: łańcuchowe
A6: ='Dane do korelacji'!A16 -> 1987 | B6: =SUM('Dane do korelacji'!B16:G16) -> 10649.6 | C6: =SUM('Dane do korelacji'!H16:L16) -> 4274.4 | V6: =A2 -> 1983 | W6: =C2-C$2 -> 0 | Y6: =(C2-C$2)/C$2 -> 0 | AA6: =C2/C$2 -> 1
A7: ='Dane do korelacji'!A17 -> 1988 | B7: =SUM('Dane do korelacji'!B17:G17) -> 10702 | C7: =SUM('Dane do korelacji'!H17:L17) -> 5408.1 | V7: =A3 -> 1984 | W7: =C3-C$2 -> 250.3 | X7: =C3-C2 -> 250.3 | Y7: =(C3-C$2)/C$2 -> 4.7585551 | Z7: =(C3-C2)/C2 -> 4.7585551 | AA7: =C3/C$2 -> 5.7585551 | AB7: =C3/C2 -> 5.7585551
A8: ='Dane do korelacji'!A18 -> 1989 | B8: =SUM('Dane do korelacji'!B18:G18) -> 9527 | C8: =SUM('Dane do korelacji'!H18:L18) -> 6642.3 | V8: =A4 -> 1985 | W8: =C4-C$2 -> 1050.4 | X8: =C4-C3 -> 800.1 | Y8: =(C4-C$2)/C$2 -> 19.969582 | Z8: =(C4-C3)/C3 -> 2.6414658 | AA8: =C4/C$2 -> 20.969582 | AB8: =C4/C3 -> 3.6414658
A9: ='Dane do korelacji'!A19 -> 1990 | B9: =SUM('Dane do korelacji'!B19:G19) -> 9118.2 | C9: =SUM('Dane do korelacji'!H19:L19) -> 8462.4 | E9: Korelacja | V9: =A5 -> 1986 | W9: =C5-C$2 -> 2533.2 | X9: =C5-C4 -> 1482.8 | Y9: =(C5-C$2)/C$2 -> 48.159696 | Z9: =(C5-C4)/C4 -> 1.3443336 | AA9: =C5/C$2 -> 49.159696 | AB9: =C5/C4 -> 2.3443336
A10: ='Dane do korelacji'!A20 -> 1991 | B10: =SUM('Dane do korelacji'!B20:G20) -> 7479.5 | C10: =SUM('Dane do korelacji'!H20:L20) -> 10046.9 | E10: Kowariancja | F10: Cov(X,Y)= | G10: =_xlfn.COVARIANCE.P('Analogi vs kompakty'!B2:B18,'Analogi vs kompakty'!C2:C18) -> -25263318 | V10: =A6 -> 1987 | W10: =C6-C$2 -> 4221.8 | X10: =C6-C5 -> 1688.6 | Y10: =(C6-C$2)/C$2 -> 80.262357 | Z10: =(C6-C5)/C5 -> 0.65302808 | AA10: =C6/C$2 -> 81.262357 | AB10: =C6/C5 -> 1.6530281
A11: ='Dane do korelacji'!A21 -> 1992 | B11: =SUM('Dane do korelacji'!B21:G21) -> 7590.3 | C11: =SUM('Dane do korelacji'!H21:L21) -> 12007.7 | E11: Wsp. Korelacji | F11: r= | G11: =G10/(_xlfn.STDEV.P(B2:B18)*_xlfn.STDEV.P(C2:C18)) -> -0.97841192 | V11: =A7 -> 1988 | W11: =C7-C$2 -> 5355.5 | X11: =C7-C6 -> 1133.7 | Y11: =(C7-C$2)/C$2 -> 101.81559 | Z11: =(C7-C6)/C6 -> 0.26523021 | AA11: =C7/C$2 -> 102.81559 | AB11: =C7/C6 -> 1.2652302
A12: ='Dane do korelacji'!A22 -> 1993 | B12: =SUM('Dane do korelacji'!B22:G22) -> 6908.2 | C12: =SUM('Dane do korelacji'!H22:L22) -> 14276.8 | V12: =A8 -> 1989 | W12: =C8-C$2 -> 6589.7 | X12: =C8-C7 -> 1234.2 | Y12: =(C8-C$2)/C$2 -> 125.27947 | Z12: =(C8-C7)/C7 -> 0.22821324 | AA12: =C8/C$2 -> 126.27947 | AB12: =C8/C7 -> 1.2282132
A13: ='Dane do korelacji'!A23 -> 1994 | B13: =SUM('Dane do korelacji'!B23:G23) -> 6818.3 | C13: =SUM('Dane do korelacji'!H23:L23) -> 17993.6 | E13: Regresja liniowa | V13: =A9 -> 1990 | W13: =C9-C$2 -> 8409.8 | X13: =C9-C8 -> 1820.1 | Y13: =(C9-C$2)/C$2 -> 159.88213 | Z13: =(C9-C8)/C8 -> 0.27401653 | AA13: =C9/C$2 -> 160.88213 | AB13: =C9/C8 -> 1.2740165
A14: ='Dane do korelacji'!A24 -> 1995 | B14: =SUM('Dane do korelacji'!B24:G24) -> 5221.7 | C14: =SUM('Dane do korelacji'!H24:L24) -> 19411 | E14: Współczynnik regresji | F14: b= | G14: =G10/(Obliczenia!N23^2) -> -2.4960617 | V14: =A10 -> 1991 | W14: =C10-C$2 -> 9994.3 | X14: =C10-C9 -> 1584.5 | Y14: =(C10-C$2)/C$2 -> 190.0057 | Z14: =(C10-C9)/C9 -> 0.18724003 | AA14: =C10/C$2 -> 191.0057 | AB14: =C10/C9 -> 1.18724
A15: ='Dane do korelacji'!A25 -> 1996 | B15: =SUM('Dane do korelacji'!B25:G25) -> 4231.4 | C15: =SUM('Dane do korelacji'!H25:L25) -> 20109.3 | E15: Współczynnik determinacji | F15: R^2= | G15: =G11^2 -> 0.95728989 | V15: =A11 -> 1992 | W15: =C11-C$2 -> 11955.1 | X15: =C11-C10 -> 1960.8 | Y15: =(C11-C$2)/C$2 -> 227.28327 | Z15: =(C11-C10)/C10 -> 0.19516468 | AA15: =C11/C$2 -> 228.28327 | AB15: =C11/C10 -> 1.1951647
A16: ='Dane do korelacji'!A26 -> 1997 | B16: =SUM('Dane do korelacji'!B26:G26) -> 3275 | C16: =SUM('Dane do korelacji'!H26:L26) -> 19956 | F16: a= | G16: =H27 -> 30565.271 | V16: =A12 -> 1993 | W16: =C12-C$2 -> 14224.2 | X16: =C12-C11 -> 2269.1 | Y16: =(C12-C$2)/C$2 -> 270.42205 | Z16: =(C12-C11)/C11 -> 0.18897041 | AA16: =C12/C$2 -> 271.42205 | AB16: =C12/C11 -> 1.1889704
A17: ='Dane do korelacji'!A27 -> 1998 | B17: =SUM('Dane do korelacji'!B27:G27) -> 2942.4 | C17: =SUM('Dane do korelacji'!H27:L27) -> 22688.5 | E17: Model regresji liniowej | F17: y= | G17: -2,5x+30565,27 | V17: =A13 -> 1994 | W17: =C13-C$2 -> 17941 | X17: =C13-C12 -> 3716.8 | Y17: =(C13-C$2)/C$2 -> 341.08365 | Z17: =(C13-C12)/C12 -> 0.26033845 | AA17: =C13/C$2 -> 342.08365 | AB17: =C13/C12 -> 1.2603385
A18: ='Dane do korelacji'!A28 -> 1999 | B18: =SUM('Dane do korelacji'!B28:G28) -> 2138.6 | C18: =SUM('Dane do korelacji'!H28:L28) -> 24536.1 | V18: =A14 -> 1995 | W18: =C14-C$2 -> 19358.4 | X18: =C14-C13 -> 1417.4 | Y18: =(C14-C$2)/C$2 -> 368.03042 | Z18: =(C14-C13)/C13 -> 0.078772452 | AA18: =C14/C$2 -> 369.03042 | AB18: =C14/C13 -> 1.0787725
B19: X | C19: Y | V19: =A15 -> 1996 | W19: =C15-C$2 -> 20056.7 | X19: =C15-C14 -> 698.3 | Y19: =(C15-C$2)/C$2 -> 381.30608 | Z19: =(C15-C14)/C14 -> 0.035974447 | AA19: =C15/C$2 -> 382.30608 | AB19: =C15/C14 -> 1.0359744
E20: Można powiedzieć, że zależność między dwiema cechami jest bardzo duża, praktycznie liniowa. Kierunek zależności jest ujemny, czyli wzrost jednej cechy powoduje spadek drugiej. Co więcej wzrost wartości płyt kompaktowych o 1 powoduje spadek wartości płyt analogowych o 2,5. Dodatkowo aż 96% zmienności wartości płyt kompaktowych zostało wyjaśnionych przez model regresji liniowej | V20: =A16 -> 1997 | W20: =C16-C$2 -> 19903.4 | X20: =C16-C15 -> -153.3 | Y20: =(C16-C$2)/C$2 -> 378.39163 | Z20: =(C16-C15)/C15 -> -0.0076233385 | AA20: =C16/C$2 -> 379.39163 | AB20: =C16/C15 -> 0.99237666
V21: =A17 -> 1998 | W21: =C17-C$2 -> 22635.9 | X21: =C17-C16 -> 2732.5 | Y21: =(C17-C$2)/C$2 -> 430.3403 | Z21: =(C17-C16)/C16 -> 0.13692624 | AA21: =C17/C$2 -> 431.3403 | AB21: =C17/C16 -> 1.1369262
V22: =A18 -> 1999 | W22: =C18-C$2 -> 24483.5 | X22: =C18-C17 -> 1847.6 | Y22: =(C18-C$2)/C$2 -> 465.46578 | Z22: =(C18-C17)/C17 -> 0.081433325 | AA22: =C18/C$2 -> 466.46578 | AB22: =C18/C17 -> 1.0814333
U24: średni przyrost absolutny łańcuchowy | X24: =SUM(X7:X22)/16 -> 1530.2188
A26: Wyznaczmy współczynniki a i b metodą mecierzową | K26: Prognoza
F27: a | G27: = | H27: =AO62 -> 30565.271
A28: A | C28: y | F28: b | H28: =AO63 -> -2.4960617 | K28: Postaramy się wyznaczyć teoretyczną wartość nośników analogowych dla kolejnych lat, w zależności od wartości płyt kompaktowych. Wykożystamy do tego średni przyrzyrost absolutny łańcuchowy dla płyt kompaktowych
A29: 1 | B29: 11531 | C29: 52.6
A30: 1 | B30: 12409.2 | C30: 302.9
A31: 1 | B31: 11250.7 | C31: 1103 | Q31: Z danej prognozy, wyznaczonej współczynnikiem regresji liniowej, możemy odczytać, że wartości nośników analogowych w 2003 roku powinny osiągnąć około 0 mld, co nie mija się z prawdą, ponieważ po 2003 ich warości na szeroką skalę branży muzycznej były nieznaczące (mniej niż 100 mld rocznie). Dane po prawej stronie to rzeczywiste przychodzy ze sprzedaży nośników analogowych. | U31: lata | V31: =B1 -> Analogowe
A32: 1 | B32: 10315.9 | C32: 2585.8 | U32: ='Dane do korelacji'!A28 -> 1999 | V32: =SUM('Dane do korelacji'!B28:G28) -> 2138.6
A33: 1 | B33: 10649.6 | C33: 4274.4 | U33: ='Dane do korelacji'!A29 -> 2000 | V33: =SUM('Dane do korelacji'!B29:G29) -> 1211.3
A34: 1 | B34: 10702 | C34: 5408.1 | U34: ='Dane do korelacji'!A30 -> 2001 | V34: =SUM('Dane do korelacji'!B30:G30) -> 726.3
A35: 1 | B35: 9527 | C35: 6642.3 | K35: rok | L35: =C1 -> Kompaktowe | M35: =B1 -> Analogowe | U35: ='Dane do korelacji'!A31 -> 2002 | V35: =SUM('Dane do korelacji'!B31:G31) -> 432.2
A36: 1 | B36: 9118.2 | C36: 8462.4 | K36: =A18 -> 1999 | L36: =C18 -> 24536.1 | M36: =B18 -> 2138.6 | U36: ='Dane do korelacji'!A32 -> 2003 | V36: =SUM('Dane do korelacji'!B32:G32) -> 250.5
A37: 1 | B37: 7479.5 | C37: 10046.9 | J37: Prognoza | K37: 2000 | L37: =L36+X$24 -> 26066.319 | M37: =(30565-L37)/2.4961 -> 1802.2841 | U37: ='Dane do korelacji'!A33 -> 2004 | V37: =SUM('Dane do korelacji'!B33:G33) -> 101.4
A38: 1 | B38: 7590.3 | C38: 12007.7 | K38: 2001 | L38: =L37+X$24 -> 27596.537 | M38: =(30565-L38)/2.4961 -> 1189.2402 | U38: ='Dane do korelacji'!A34 -> 2005 | V38: =SUM('Dane do korelacji'!B34:G34) -> 63.2
A39: 1 | B39: 6908.2 | C39: 14276.8 | K39: 2002 | L39: =L38+X$24 -> 29126.756 | M39: =(30565-L39)/2.4961 -> 576.19637 | U39: ='Dane do korelacji'!A35 -> 2006 | V39: =SUM('Dane do korelacji'!B35:G35) -> 44.3
A40: 1 | B40: 6818.3 | C40: 17993.6 | K40: 2003 | L40: =L39+X$24 -> 30656.975 | M40: =(30565-L40)/2.4961 -> -36.847482 | U40: ='Dane do korelacji'!A36 -> 2007 | V40: =SUM('Dane do korelacji'!B36:G36) -> 44
A41: 1 | B41: 5221.7 | C41: 19411
A42: 1 | B42: 4231.4 | C42: 20109.3
...
